2021-05-29 18:16:27,349 INFO  * Running on http://127.0.0.1:5000/ (Press CTRL+C to quit)
2021-05-29 18:16:32,779 INFO  * Running on http://127.0.0.1:5000/ (Press CTRL+C to quit)
2021-05-29 18:16:51,411 INFO 127.0.0.1 - - [29/May/2021 18:16:51] "GET / HTTP/1.1" 200 -
2021-05-29 18:16:55,819 INFO Form submitted successfully id_order:265 curency:978 amount:1.00
2021-05-29 18:16:55,820 INFO 127.0.0.1 - - [29/May/2021 18:16:55] "POST / HTTP/1.1" 200 -
2021-05-29 18:18:24,872 INFO  * Running on http://127.0.0.1:5000/ (Press CTRL+C to quit)
2021-05-29 22:29:43,355 INFO  * Running on http://127.0.0.1:5000/ (Press CTRL+C to quit)
2021-05-29 22:29:43,356 INFO  * Restarting with stat
2021-05-29 22:29:43,534 WARNING  * Debugger is active!
2021-05-29 22:29:43,595 INFO  * Debugger PIN: 346-691-044
2021-05-29 22:29:58,548 INFO 127.0.0.1 - - [29/May/2021 22:29:58] "GET / HTTP/1.1" 200 -
2021-05-29 22:30:03,321 ERROR error: date/time field value out of range: "29/05/2021 22:30:02"
LINE 1: ... date, description) VALUES (213.00,978, TIMESTAMP '29/05/202...
                                                             ^
HINT:  Perhaps you need a different "datestyle" setting.
Traceback (most recent call last):
  File "/home/artyom/PycharmProjects/try10000/app.py", line 22, in index
    return pay_eur(payment_amount, product_description)
  File "/home/artyom/PycharmProjects/try10000/functiones.py", line 124, in pay_eur
    write(payment_amount, currency, product_description, conn)
  File "/home/artyom/PycharmProjects/try10000/database.py", line 14, in write
    conn.cursor().execute(query)
psycopg2.errors.DatetimeFieldOverflow: date/time field value out of range: "29/05/2021 22:30:02"
LINE 1: ... date, description) VALUES (213.00,978, TIMESTAMP '29/05/202...
                                                             ^
HINT:  Perhaps you need a different "datestyle" setting.

2021-05-29 22:30:03,323 INFO 127.0.0.1 - - [29/May/2021 22:30:03] "POST / HTTP/1.1" 200 -
2021-05-29 22:31:27,308 INFO  * Detected change in '/home/artyom/PycharmProjects/try10000/database.py', reloading
2021-05-29 22:31:27,341 INFO  * Restarting with stat
2021-05-29 22:31:27,508 WARNING  * Debugger is active!
2021-05-29 22:31:27,508 INFO  * Debugger PIN: 346-691-044
2021-05-29 22:31:48,668 INFO 127.0.0.1 - - [29/May/2021 22:31:48] "GET / HTTP/1.1" 200 -
2021-05-29 22:31:52,741 ERROR error: date/time field value out of range: "29/05/2021 22:31:52"
LINE 1: ...y, date, description) VALUES (4.00,840, TIMESTAMP '29/05/202...
                                                             ^
HINT:  Perhaps you need a different "datestyle" setting.
Traceback (most recent call last):
  File "/home/artyom/PycharmProjects/try10000/app.py", line 24, in index
    return pay_usd(payment_amount, product_description)
  File "/home/artyom/PycharmProjects/try10000/functiones.py", line 141, in pay_usd
    write(payment_amount, currency, product_description, conn)
  File "/home/artyom/PycharmProjects/try10000/database.py", line 15, in write
    conn.cursor().execute(query)
psycopg2.errors.DatetimeFieldOverflow: date/time field value out of range: "29/05/2021 22:31:52"
LINE 1: ...y, date, description) VALUES (4.00,840, TIMESTAMP '29/05/202...
                                                             ^
HINT:  Perhaps you need a different "datestyle" setting.

2021-05-29 22:31:52,743 INFO 127.0.0.1 - - [29/May/2021 22:31:52] "POST / HTTP/1.1" 200 -
2021-05-29 22:32:33,066 INFO  * Running on http://127.0.0.1:5000/ (Press CTRL+C to quit)
2021-05-29 22:32:33,067 INFO  * Restarting with stat
2021-05-29 22:32:33,238 WARNING  * Debugger is active!
2021-05-29 22:32:33,239 INFO  * Debugger PIN: 346-691-044
2021-05-29 22:32:35,130 INFO 127.0.0.1 - - [29/May/2021 22:32:35] "GET / HTTP/1.1" 200 -
2021-05-29 22:32:38,582 ERROR error: FATAL:  database " postgresql-defined-71759" does not exist
Traceback (most recent call last):
  File "/home/artyom/PycharmProjects/try10000/app.py", line 22, in index
    return pay_eur(payment_amount, product_description)
  File "/home/artyom/PycharmProjects/try10000/functiones.py", line 122, in pay_eur
    conn = get_conn()
  File "/home/artyom/PycharmProjects/try10000/database.py", line 19, in get_conn
    return psycopg2.connect(database=DBNAME)
  File "/home/artyom/PycharmProjects/try10000/venv/lib/python3.8/site-packages/psycopg2/__init__.py", line 127, in connect
    conn = _connect(dsn, connection_factory=connection_factory, **kwasync)
psycopg2.OperationalError: FATAL:  database " postgresql-defined-71759" does not exist

2021-05-29 22:32:38,583 INFO 127.0.0.1 - - [29/May/2021 22:32:38] "POST / HTTP/1.1" 200 -
2021-05-29 22:33:01,085 INFO  * Running on http://127.0.0.1:5000/ (Press CTRL+C to quit)
2021-05-29 22:33:01,086 INFO  * Restarting with stat
2021-05-29 22:33:01,255 WARNING  * Debugger is active!
2021-05-29 22:33:01,256 INFO  * Debugger PIN: 346-691-044
2021-05-29 22:33:02,914 INFO 127.0.0.1 - - [29/May/2021 22:33:02] "GET / HTTP/1.1" 200 -
2021-05-29 22:33:06,157 INFO Form submitted successfully id_order:266 curency:978 amount:4.00
2021-05-29 22:33:06,158 INFO 127.0.0.1 - - [29/May/2021 22:33:06] "POST / HTTP/1.1" 200 -
